<sdf version='1.10'>
  <world name='gpu_lidar_sensor'>
    <physics name='1ms' type='ignored'>
      <max_step_size>0.001</max_step_size>
      <real_time_factor>1</real_time_factor>
      <real_time_update_rate>1000</real_time_update_rate>
    </physics>
    <plugin name='gz::sim::systems::Physics' filename='gz-sim-physics-system'/>
    <plugin name='gz::sim::systems::Sensors' filename='gz-sim-sensors-system'>
      <render_engine>ogre2</render_engine>
    </plugin>

    <plugin name='gz::sim::systems::SceneBroadcaster' filename='gz-sim-scene-broadcaster-system'/>
    <plugin name='gz::sim::systems::UserCommands' filename='gz-sim-user-commands-system'/>

    <plugin name='gz::sim::systems::TriggeredPublisher' filename='gz-sim-triggered-publisher-system'>
      <input type='gz.msgs.Int32' topic='/keyboard/keypress'>
        <match field='data'>88</match>
      </input>
      <output type='gz.msgs.Twist' topic='/cmd_vel'>linear: {x: 0.0}, angular: {z: 0.0}</output>
    </plugin>
    <plugin name='gz::sim::systems::TriggeredPublisher' filename='gz-sim-triggered-publisher-system'>
      <input type='gz.msgs.Int32' topic='/keyboard/keypress'>
        <match field='data'>16777234</match>
      </input>
      <output type='gz.msgs.Twist' topic='/cmd_vel'>linear: {x: 0.0}, angular: {z: 0.5}</output>
    </plugin>
    <plugin name='gz::sim::systems::TriggeredPublisher' filename='gz-sim-triggered-publisher-system'>
      <input type='gz.msgs.Int32' topic='/keyboard/keypress'>
        <match field='data'>16777235</match>
      </input>
      <output type='gz.msgs.Twist' topic='/cmd_vel'>linear: {x: 1}, angular: {z: 0.0}</output>
    </plugin>
    <plugin name='gz::sim::systems::TriggeredPublisher' filename='gz-sim-triggered-publisher-system'>
      <input type='gz.msgs.Int32' topic='/keyboard/keypress'>
        <match field='data'>16777236</match>
      </input>
      <output type='gz.msgs.Twist' topic='/cmd_vel'>linear: {x: 0.0}, angular: {z: -0.5}</output>
    </plugin>
    <plugin name='gz::sim::systems::TriggeredPublisher' filename='gz-sim-triggered-publisher-system'>
      <input type='gz.msgs.Int32' topic='/keyboard/keypress'>
        <match field='data'>16777237</match>
      </input>
      <output type='gz.msgs.Twist' topic='/cmd_vel'>linear: {x: -1}, angular: {z: 0.0}</output>
    </plugin>
    <gravity>0 0 -9.8000000000000007</gravity>
    <magnetic_field>5.5644999999999998e-06 2.2875799999999999e-05 -4.2388400000000002e-05</magnetic_field>
    <atmosphere type='adiabatic'/>
    <scene>
      <ambient>0.400000006 0.400000006 0.400000006 1</ambient>
      <background>0.699999988 0.699999988 0.699999988 1</background>
      <shadows>true</shadows>
    </scene>
    <model name='ground_plane'>
      <static>true</static>
      <link name='link'>
        <collision name='collision'>
          <geometry>
            <box>
              <size>20 20 0.10000000000000001</size>
            </box>
          </geometry>
          <surface>
            <friction>
              <ode/>
            </friction>
            <bounce/>
            <contact/>
          </surface>
        </collision>
        <visual name='visual'>
          <geometry>
            <box>
              <size>20 20 0.10000000000000001</size>
            </box>
          </geometry>
          <material>
            <ambient>0.800000012 0.800000012 0.800000012 1</ambient>
            <diffuse>0.800000012 0.800000012 0.800000012 1</diffuse>
            <specular>0.800000012 0.800000012 0.800000012 1</specular>
          </material>
        </visual>
        <pose>0 0 0 0 0 0</pose>
        <inertial>
          <pose>0 0 0 0 0 0</pose>
          <mass>1</mass>
          <inertia>
            <ixx>1</ixx>
            <ixy>0</ixy>
            <ixz>0</ixz>
            <iyy>1</iyy>
            <iyz>0</iyz>
            <izz>1</izz>
          </inertia>
        </inertial>
        <enable_wind>false</enable_wind>
      </link>
      <pose>0 0 0 0 0 0</pose>
      <self_collide>false</self_collide>
    </model>
    <model name='vehicle_blue'>
      <pose>-0.035834578150075111 1.5971245450780076 0.37499999219499147 -6.0750216306054131e-14 -8.129450753932596e-10 1.0786998786598911</pose>
      <link name='chassis'>
        <pose>-0.15142700000000001 0 0.17499999999999999 0 0 0</pose>
        <inertial>
          <mass>1.14395</mass>
          <inertia>
            <ixx>0.126164</ixx>
            <ixy>0</ixy>
            <ixz>0</ixz>
            <iyy>0.41651899999999997</iyy>
            <iyz>0</iyz>
            <izz>0.481014</izz>
          </inertia>
          <pose>0 0 0 0 0 0</pose>
        </inertial>
        <visual name='visual'>
          <geometry>
            <box>
              <size>2.0114200000000002 1 0.56872599999999995</size>
            </box>
          </geometry>
          <material>
            <ambient>0.5 0.5 1 1</ambient>
            <diffuse>0.5 0.5 1 1</diffuse>
            <specular>0 0 1 1</specular>
          </material>
        </visual>
        <collision name='collision'>
          <geometry>
            <box>
              <size>2.0114200000000002 1 0.56872599999999995</size>
            </box>
          </geometry>
          <surface>
            <friction>
              <ode/>
            </friction>
            <bounce/>
            <contact/>
          </surface>
        </collision>
        <enable_wind>false</enable_wind>
      </link>
      <link name='lidar_link'>
        <pose>0.050000000000000044 5.5511151231257827e-16 0.3000000000000001 0 0 0</pose>
        <sensor name='gpu_lidar' type='gpu_lidar'>
          <pose>0 0 0 0 0 0</pose>
          <topic>lidar</topic>
          <update_rate>10</update_rate>
          <enable_metrics>false</enable_metrics>
          <lidar>
            <scan>
              <horizontal>
                <samples>640</samples>
                <resolution>1</resolution>
                <min_angle>-1.396263</min_angle>
                <max_angle>1.396263</max_angle>
              </horizontal>
              <vertical>
                <samples>16</samples>
                <min_angle>-0.261799</min_angle>
                <max_angle>0.261799</max_angle>
                <resolution>1</resolution>
              </vertical>
            </scan>
            <range>
              <min>0.080000000000000002</min>
              <max>10</max>
              <resolution>0.01</resolution>
            </range>
            <noise>
              <type>none</type>
              <mean>0</mean>
              <stddev>0</stddev>
            </noise>
            <visibility_mask>4294967295</visibility_mask>
          </lidar>
        </sensor>
        <inertial>
          <pose>0 0 0 0 0 0</pose>
          <mass>1</mass>
          <inertia>
            <ixx>1</ixx>
            <ixy>0</ixy>
            <ixz>0</ixz>
            <iyy>1</iyy>
            <iyz>0</iyz>
            <izz>1</izz>
          </inertia>
        </inertial>
        <enable_wind>false</enable_wind>
      </link>
      <joint name='lidar_joint' type='fixed'>
        <parent>chassis</parent>
        <child>lidar_link</child>
        <pose>0 0 0 0 0 0</pose>
      </joint>
      <link name='base_footprint'>
        <pose>0 2.2204460492503131e-16 5.5511151231257827e-17 0 0 0</pose>
        <inertial>
          <pose>0 0 0 0 0 0</pose>
          <mass>1</mass>
          <inertia>
            <ixx>1</ixx>
            <ixy>0</ixy>
            <ixz>0</ixz>
            <iyy>1</iyy>
            <iyz>0</iyz>
            <izz>1</izz>
          </inertia>
        </inertial>
        <enable_wind>false</enable_wind>
      </link>
      <joint name='base_footprint_joint' type='fixed'>
        <parent>base_footprint</parent>
        <child>chassis</child>
        <pose>0 0 0 0 0 0</pose>
      </joint>
      <link name='left_wheel'>
        <pose>0.55428299999999986 0.62502900000000017 -0.024999999999999911 1.5706958283533601 0.28913651168845522 3.1415639990030964</pose>
        <inertial>
          <mass>2</mass>
          <inertia>
            <ixx>0.14583299999999999</ixx>
            <ixy>0</ixy>
            <ixz>0</ixz>
            <iyy>0.14583299999999999</iyy>
            <iyz>0</iyz>
            <izz>0.125</izz>
          </inertia>
          <pose>0 0 0 0 0 0</pose>
        </inertial>
        <visual name='visual'>
          <geometry>
            <sphere>
              <radius>0.29999999999999999</radius>
            </sphere>
          </geometry>
          <material>
            <ambient>0.200000003 0.200000003 0.200000003 1</ambient>
            <diffuse>0.200000003 0.200000003 0.200000003 1</diffuse>
            <specular>0.200000003 0.200000003 0.200000003 1</specular>
          </material>
        </visual>
        <collision name='collision'>
          <geometry>
            <sphere>
              <radius>0.29999999999999999</radius>
            </sphere>
          </geometry>
          <surface>
            <friction>
              <ode>
                <mu>1</mu>
                <mu2>1</mu2>
                <slip1>0.035000000000000003</slip1>
                <slip2>0</slip2>
                <fdir1>0 0 1</fdir1>
              </ode>
              <bullet>
                <friction>1</friction>
                <friction2>1</friction2>
                <rolling_friction>0.10000000000000001</rolling_friction>
              </bullet>
            </friction>
            <bounce/>
            <contact/>
          </surface>
        </collision>
        <enable_wind>false</enable_wind>
      </link>
      <link name='right_wheel'>
        <pose>0.55428199999999994 -0.62502899999999995 -0.025000000000000078 -1.5705978474873934 1.0640624916202983 0.00017353727030548061</pose>
        <inertial>
          <mass>2</mass>
          <inertia>
            <ixx>0.14583299999999999</ixx>
            <ixy>0</ixy>
            <ixz>0</ixz>
            <iyy>0.14583299999999999</iyy>
            <iyz>0</iyz>
            <izz>0.125</izz>
          </inertia>
          <pose>0 0 0 0 0 0</pose>
        </inertial>
        <visual name='visual'>
          <geometry>
            <sphere>
              <radius>0.29999999999999999</radius>
            </sphere>
          </geometry>
          <material>
            <ambient>0.200000003 0.200000003 0.200000003 1</ambient>
            <diffuse>0.200000003 0.200000003 0.200000003 1</diffuse>
            <specular>0.200000003 0.200000003 0.200000003 1</specular>
          </material>
        </visual>
        <collision name='collision'>
          <geometry>
            <sphere>
              <radius>0.29999999999999999</radius>
            </sphere>
          </geometry>
          <surface>
            <friction>
              <ode>
                <mu>1</mu>
                <mu2>1</mu2>
                <slip1>0.035000000000000003</slip1>
                <slip2>0</slip2>
                <fdir1>0 0 1</fdir1>
              </ode>
              <bullet>
                <friction>1</friction>
                <friction2>1</friction2>
                <rolling_friction>0.10000000000000001</rolling_friction>
              </bullet>
            </friction>
            <bounce/>
            <contact/>
          </surface>
        </collision>
        <enable_wind>false</enable_wind>
      </link>
      <link name='caster'>
        <pose>-0.95713800000000016 2.2204460492503131e-16 -0.12499999999999994 0.7972077141814552 0.46833514056811765 -1.9048928436259978</pose>
        <inertial>
          <mass>1</mass>
          <inertia>
            <ixx>0.10000000000000001</ixx>
            <ixy>0</ixy>
            <ixz>0</ixz>
            <iyy>0.10000000000000001</iyy>
            <iyz>0</iyz>
            <izz>0.10000000000000001</izz>
          </inertia>
          <pose>0 0 0 0 0 0</pose>
        </inertial>
        <visual name='visual'>
          <geometry>
            <sphere>
              <radius>0.20000000000000001</radius>
            </sphere>
          </geometry>
          <material>
            <ambient>0.200000003 0.200000003 0.200000003 1</ambient>
            <diffuse>0.200000003 0.200000003 0.200000003 1</diffuse>
            <specular>0.200000003 0.200000003 0.200000003 1</specular>
          </material>
        </visual>
        <collision name='collision'>
          <geometry>
            <sphere>
              <radius>0.20000000000000001</radius>
            </sphere>
          </geometry>
          <surface>
            <friction>
              <ode/>
            </friction>
            <bounce/>
            <contact/>
          </surface>
        </collision>
        <enable_wind>false</enable_wind>
      </link>
      <joint name='left_wheel_joint' type='revolute'>
        <parent>chassis</parent>
        <child>left_wheel</child>
        <axis>
          <xyz>0 0 1</xyz>
          <limit>
            <lower>-1.7976900000000001e+308</lower>
            <upper>1.7976900000000001e+308</upper>
            <effort>inf</effort>
            <velocity>inf</velocity>
            <stiffness>100000000</stiffness>
            <dissipation>1</dissipation>
          </limit>
          <dynamics>
            <spring_reference>0</spring_reference>
            <spring_stiffness>0</spring_stiffness>
            <damping>0</damping>
            <friction>0</friction>
          </dynamics>
        </axis>
        <pose>0 0 1.1102230246251565e-16 0 0 0</pose>
      </joint>
      <joint name='right_wheel_joint' type='revolute'>
        <parent>chassis</parent>
        <child>right_wheel</child>
        <axis>
          <xyz>0 0 1</xyz>
          <limit>
            <lower>-1.7976900000000001e+308</lower>
            <upper>1.7976900000000001e+308</upper>
            <effort>inf</effort>
            <velocity>inf</velocity>
            <stiffness>100000000</stiffness>
            <dissipation>1</dissipation>
          </limit>
          <dynamics>
            <spring_reference>0</spring_reference>
            <spring_stiffness>0</spring_stiffness>
            <damping>0</damping>
            <friction>0</friction>
          </dynamics>
        </axis>
        <pose>-1.1102230246251565e-16 0 0 0 0 0</pose>
      </joint>
      <joint name='caster_wheel' type='ball'>
        <parent>chassis</parent>
        <child>caster</child>
        <pose>0 0 0 0 0 0</pose>
      </joint>
      <plugin name='gz::sim::systems::DiffDrive' filename='gz-sim-diff-drive-system'>
        <left_joint>left_wheel_joint</left_joint>
        <right_joint>right_wheel_joint</right_joint>
        <wheel_separation>1.25</wheel_separation>
        <wheel_radius>0.3</wheel_radius>
        <max_linear_acceleration>1</max_linear_acceleration>
        <min_linear_acceleration>-1</min_linear_acceleration>
        <max_angular_acceleration>2</max_angular_acceleration>
        <min_angular_acceleration>-2</min_angular_acceleration>
        <max_linear_velocity>1</max_linear_velocity>
        <min_linear_velocity>-1</min_linear_velocity>
        <max_angular_velocity>1</max_angular_velocity>
        <min_angular_velocity>-1</min_angular_velocity>
        <topic>cmd_vel</topic>
        <tf_topic>tf_foo</tf_topic>
        <odom_topic>odom</odom_topic>
        <frame_id>odom</frame_id>
        <child_frame_id>vehicle_blue</child_frame_id>
        <odom_publisher_frequency>30</odom_publisher_frequency>
      </plugin>
      <plugin name='ignition::gazebo::systems::JointStatePublisher' filename='ignition-gazebo-joint-state-publisher-system'/>
      <plugin name='ignition::gazebo::systems::PosePublisher' filename='ignition-gazebo-pose-publisher-system'>
        <publish_link_pose>true</publish_link_pose>
        <use_pose_vector_msg>true</use_pose_vector_msg>
        <publish_sensor_pose>true</publish_sensor_pose>
      </plugin>
      <static>false</static>
      <self_collide>false</self_collide>
    </model>
    <model name='box'>
      <pose>5.3964481353759766 2 0.54999999632499452 6.874951275213477e-18 -6.830121254236544e-18 -7.0274180069871263e-19</pose>
      <link name='box_link'>
        <inertial>
          <inertia>
            <ixx>1</ixx>
            <ixy>0</ixy>
            <ixz>0</ixz>
            <iyy>1</iyy>
            <iyz>0</iyz>
            <izz>1</izz>
          </inertia>
          <mass>1</mass>
          <pose>0 0 0 0 0 0</pose>
        </inertial>
        <collision name='box_collision'>
          <geometry>
            <box>
              <size>1 1 1</size>
            </box>
          </geometry>
          <surface>
            <friction>
              <ode/>
            </friction>
            <bounce/>
            <contact/>
          </surface>
        </collision>
        <visual name='box_visual'>
          <geometry>
            <box>
              <size>1 1 1</size>
            </box>
          </geometry>
          <material>
            <ambient>1 0 0 1</ambient>
            <diffuse>1 0 0 1</diffuse>
            <specular>1 0 0 1</specular>
          </material>
        </visual>
        <pose>0 0 0 0 0 0</pose>
        <enable_wind>false</enable_wind>
      </link>
      <static>false</static>
      <self_collide>false</self_collide>
    </model>
    <model name='cylinder'>
      <pose>3.7591266286598506 -3.8982623502909348 0.54999999631412899 7.3983832888188797e-17 -6.5425931891392009e-18 -2.8382332379726406e-17</pose>
      <link name='cylinder_link'>
        <inertial>
          <inertia>
            <ixx>0.14580000000000001</ixx>
            <ixy>0</ixy>
            <ixz>0</ixz>
            <iyy>0.14580000000000001</iyy>
            <iyz>0</iyz>
            <izz>0.125</izz>
          </inertia>
          <mass>1</mass>
          <pose>0 0 0 0 0 0</pose>
        </inertial>
        <collision name='cylinder_collision'>
          <geometry>
            <cylinder>
              <radius>0.5</radius>
              <length>1</length>
            </cylinder>
          </geometry>
          <surface>
            <friction>
              <ode/>
            </friction>
            <bounce/>
            <contact/>
          </surface>
        </collision>
        <visual name='cylinder_visual'>
          <geometry>
            <cylinder>
              <radius>0.5</radius>
              <length>1</length>
            </cylinder>
          </geometry>
          <material>
            <ambient>0.300000012 0.300000012 0.300000012 1</ambient>
            <diffuse>0.699999988 0.699999988 0.699999988 1</diffuse>
            <specular>1 1 1 1</specular>
          </material>
        </visual>
        <pose>0 0 0 0 0 0</pose>
        <enable_wind>false</enable_wind>
      </link>
      <static>false</static>
      <self_collide>false</self_collide>
    </model>
    <model name='box_0'>
      <pose>-5.9654865264892578 -1.444100022315979 0.54999999019970047 -2.3932467723792971e-18 -5.5468999429129259e-18 -8.6510593755687685e-21</pose>
      <link name='box_link'>
        <inertial>
          <inertia>
            <ixx>0.16666</ixx>
            <ixy>0</ixy>
            <ixz>0</ixz>
            <iyy>0.16666</iyy>
            <iyz>0</iyz>
            <izz>0.16666</izz>
          </inertia>
          <mass>1</mass>
          <pose>0 0 0 0 0 0</pose>
        </inertial>
        <collision name='box_collision'>
          <geometry>
            <box>
              <size>1 1 1</size>
            </box>
          </geometry>
          <surface>
            <friction>
              <ode/>
            </friction>
            <bounce/>
            <contact/>
          </surface>
        </collision>
        <visual name='box_visual'>
          <geometry>
            <box>
              <size>1 1 1</size>
            </box>
          </geometry>
          <material>
            <ambient>0.300000012 0.300000012 0.300000012 1</ambient>
            <diffuse>0.699999988 0.699999988 0.699999988 1</diffuse>
            <specular>1 1 1 1</specular>
          </material>
        </visual>
        <pose>0 0 0 0 0 0</pose>
        <enable_wind>false</enable_wind>
      </link>
      <static>false</static>
      <self_collide>false</self_collide>
    </model>
    <model name='box_1'>
      <pose>3.1083164677275352 7.6065231199046277 0.54999999019970047 -4.1743863489363425e-18 -5.5569153427180631e-18 6.6675589990723449e-18</pose>
      <link name='box_link'>
        <inertial>
          <inertia>
            <ixx>0.16666</ixx>
            <ixy>0</ixy>
            <ixz>0</ixz>
            <iyy>0.16666</iyy>
            <iyz>0</iyz>
            <izz>0.16666</izz>
          </inertia>
          <mass>1</mass>
          <pose>0 0 0 0 0 0</pose>
        </inertial>
        <collision name='box_collision'>
          <geometry>
            <box>
              <size>1 1 1</size>
            </box>
          </geometry>
          <surface>
            <friction>
              <ode/>
            </friction>
            <bounce/>
            <contact/>
          </surface>
        </collision>
        <visual name='box_visual'>
          <geometry>
            <box>
              <size>1 1 1</size>
            </box>
          </geometry>
          <material>
            <ambient>0.300000012 0.300000012 0.300000012 1</ambient>
            <diffuse>0.699999988 0.699999988 0.699999988 1</diffuse>
            <specular>1 1 1 1</specular>
          </material>
        </visual>
        <pose>0 0 0 0 0 0</pose>
        <enable_wind>false</enable_wind>
      </link>
      <static>false</static>
      <self_collide>false</self_collide>
    </model>
    <model name='box_2'>
      <pose>-5.7757538736578979 7.5092163660920495 0.54999999019970047 7.0241169581865841e-19 -5.5501718279137904e-18 6.0246172301808072e-18</pose>
      <link name='box_link'>
        <inertial>
          <inertia>
            <ixx>0.16666</ixx>
            <ixy>0</ixy>
            <ixz>0</ixz>
            <iyy>0.16666</iyy>
            <iyz>0</iyz>
            <izz>0.16666</izz>
          </inertia>
          <mass>1</mass>
          <pose>0 0 0 0 0 0</pose>
        </inertial>
        <collision name='box_collision'>
          <geometry>
            <box>
              <size>1 1 1</size>
            </box>
          </geometry>
          <surface>
            <friction>
              <ode/>
            </friction>
            <bounce/>
            <contact/>
          </surface>
        </collision>
        <visual name='box_visual'>
          <geometry>
            <box>
              <size>1 1 1</size>
            </box>
          </geometry>
          <material>
            <ambient>0.300000012 0.300000012 0.300000012 1</ambient>
            <diffuse>0.699999988 0.699999988 0.699999988 1</diffuse>
            <specular>1 1 1 1</specular>
          </material>
        </visual>
        <pose>0 0 0 0 0 0</pose>
        <enable_wind>false</enable_wind>
      </link>
      <static>false</static>
      <self_collide>false</self_collide>
    </model>
    <model name='box_3'>
      <pose>-1.3822708851881016 -6.7290648142010152 0.54999999019970047 -2.9732300549718551e-18 -5.5538548931606832e-18 4.4686167483161527e-18</pose>
      <link name='box_link'>
        <inertial>
          <inertia>
            <ixx>0.16666</ixx>
            <ixy>0</ixy>
            <ixz>0</ixz>
            <iyy>0.16666</iyy>
            <iyz>0</iyz>
            <izz>0.16666</izz>
          </inertia>
          <mass>1</mass>
          <pose>0 0 0 0 0 0</pose>
        </inertial>
        <collision name='box_collision'>
          <geometry>
            <box>
              <size>1 1 1</size>
            </box>
          </geometry>
          <surface>
            <friction>
              <ode/>
            </friction>
            <bounce/>
            <contact/>
          </surface>
        </collision>
        <visual name='box_visual'>
          <geometry>
            <box>
              <size>1 1 1</size>
            </box>
          </geometry>
          <material>
            <ambient>0.300000012 0.300000012 0.300000012 1</ambient>
            <diffuse>0.699999988 0.699999988 0.699999988 1</diffuse>
            <specular>1 1 1 1</specular>
          </material>
        </visual>
        <pose>0 0 0 0 0 0</pose>
        <enable_wind>false</enable_wind>
      </link>
      <static>false</static>
      <self_collide>false</self_collide>
    </model>
    <light name='sun' type='directional'>
      <pose>0 0 10 0 0 0</pose>
      <cast_shadows>true</cast_shadows>
      <intensity>1</intensity>
      <direction>-0.5 0.10000000000000001 -0.90000000000000002</direction>
      <diffuse>0.800000012 0.800000012 0.800000012 1</diffuse>
      <specular>0.200000003 0.200000003 0.200000003 1</specular>
      <attenuation>
        <range>1000</range>
        <linear>0.01</linear>
        <constant>0.90000000000000002</constant>
        <quadratic>0.001</quadratic>
      </attenuation>
      <spot>
        <inner_angle>0</inner_angle>
        <outer_angle>0</outer_angle>
        <falloff>0</falloff>
      </spot>
    </light>
  </world>
</sdf>
